Workbook

Sheet crisk
C1: person_age | D1: person_income | E1: person_home_ownership | F1: person_emp_length | G1: loan_intent | H1: loan_grade | I1: loan_amnt | J1: loan_int_rate | K1: loan_status | L1: loan_percent_income | M1: cb_person_default_on_file | N1: cb_person_cred_hist_length
C2: 22 | D2: 59000 | E2: RENT | F2: 123 | G2: PERSONAL | H2: D | I2: 35000 | J2: 16.02 | K2: 1 | L2: 0.59 | M2: Y | N2: 3
C3: 21 | D3: 9600 | E3: OWN | F3: 5 | G3: EDUCATION | H3: B | I3: 1000 | J3: 11.14 | K3: 0 | L3: 0.1 | M3: N | N3: 2
C4: 25 | D4: 9600 | E4: MORTGAGE | F4: 1 | G4: MEDICAL | H4: C | I4: 5500 | J4: 12.87 | K4: 1 | L4: 0.57 | M4: N | N4: 3
C5: 23 | D5: 65500 | E5: RENT | F5: 4 | G5: MEDICAL | H5: C | I5: 35000 | J5: 15.23 | K5: 1 | L5: 0.53 | M5: N | N5: 2
C6: 24 | D6: 54400 | E6: RENT | F6: 8 | G6: MEDICAL | H6: C | I6: 35000 | J6: 14.27 | K6: 1 | L6: 0.55 | M6: Y | N6: 4
C7: 21 | D7: 9900 | E7: OWN | F7: 2 | G7: VENTURE | H7: A | I7: 2500 | J7: 7.14 | K7: 1 | L7: 0.25 | M7: N | N7: 2
C8: 26 | D8: 77100 | E8: RENT | F8: 8 | G8: EDUCATION | H8: B | I8: 35000 | J8: 12.42 | K8: 1 | L8: 0.45 | M8: N | N8: 3
C9: 24 | D9: 78956 | E9: RENT | F9: 5 | G9: MEDICAL | H9: B | I9: 35000 | J9: 11.11 | K9: 1 | L9: 0.44 | M9: N | N9: 4
C10: 24 | D10: 83000 | E10: RENT | F10: 8 | G10: PERSONAL | H10: A | I10: 35000 | J10: 8.9 | K10: 1 | L10: 0.42 | M10: N | N10: 2
C11: 21 | D11: 10000 | E11: OWN | F11: 6 | G11: VENTURE | H11: D | I11: 1600 | J11: 14.74 | K11: 1 | L11: 0.16 | M11: N | N11: 3
C12: 22 | D12: 85000 | E12: RENT | F12: 6 | G12: VENTURE | H12: B | I12: 35000 | J12: 10.37 | K12: 1 | L12: 0.41 | M12: N | N12: 4
C13: 21 | D13: 10000 | E13: OWN | F13: 2 | G13: HOMEIMPROVEMENT | H13: A | I13: 4500 | J13: 8.63 | K13: 1 | L13: 0.45 | M13: N | N13: 2
... C40: 25 | D40: 75000 | E40: RENT | F40: 4 | G40: HOMEIMPROVEMENT | H40: D | I40: 30000 | J40: 16.89 | K40: 1 | L40: 0.4 | M40: Y | N40: 4
C41: 23 | D41: 71500 | E41: RENT | F41: 3 | G41: DEBTCONSOLIDATION | H41: D | I41: 30000 | K41: 1 | L41: 0.42 | M41: N | N41: 4
C42: 26 | D42: 62050 | E42: RENT | F42: 6 | G42: MEDICAL | H42: E | I42: 30000 | J42: 17.99 | K42: 1 | L42: 0.41 | M42: N | N42: 2
C43: 24 | D43: 12000 | E43: OWN | F43: 4 | G43: VENTURE | H43: B | I43: 2500 | J43: 12.69 | K43: 1 | L43: 0.21 | M43: N | N43: 3
C44: 26 | D44: 300000 | E44: MORTGAGE | F44: 10 | G44: VENTURE | H44: A | I44: 20000 | J44: 7.88 | K44: 0 | L44: 0.07 | M44: N | N44: 4
C45: 23 | D45: 300000 | E45: OWN | F45: 1 | G45: EDUCATION | H45: F | I45: 24250 | J45: 19.41 | K45: 0 | L45: 0.08 | M45: Y | N45: 2
C46: 26 | D46: 300000 | E46: OWN | F46: 9 | G46: HOMEIMPROVEMENT | H46: B | I46: 10000 | J46: 10.38 | K46: 0 | L46: 0.03 | M46: N | N46: 4
C47: 26 | D47: 300000 | E47: MORTGAGE | F47: 0 | G47: EDUCATION | H47: D | I47: 25000 | J47: 15.33 | K47: 0 | L47: 0.08 | M47: N | N47: 3
C48: 25 | D48: 300000 | E48: MORTGAGE | F48: 9 | G48: HOMEIMPROVEMENT | H48: E | I48: 18000 | J48: 16.45 | K48: 0 | L48: 0.06 | M48: N | N48: 3
C49: 26 | D49: 80690 | E49: RENT | F49: 8 | G49: PERSONAL | H49: A | I49: 30000 | J49: 7.49 | K49: 1 | L49: 0.37 | M49: N | N49: 3
C50: 22 | D50: 66300 | E50: RENT | F50: 4 | G50: MEDICAL | H50: B | I50: 30000 | J50: 12.69 | K50: 1 | L50: 0.38 | M50: N | N50: 3
C51: 26 | D51: 89028 | E51: RENT | F51: 0 | G51: DEBTCONSOLIDATION | H51: A | I51: 30000 | J51: 6.62 | K51: 1 | L51: 0.34 | M51: N | N51: 3
C52: 24 | D52: 78000 | E52: RENT | F52: 4 | G52: DEBTCONSOLIDATION | H52: D | I52: 30000 | K52: 1 | L52: 0.38 | M52: Y | N52: 4
C53: 23 | D53: 78000 | E53: RENT | F53: 7 | G53: DEBTCONSOLIDATION | H53: F | I53: 30000 | J53: 18.62 | K53: 1 | L53: 0.38 | M53: Y | N53: 3
C54: 23 | D54: 92004 | E54: RENT | F54: 6 | G54: PERSONAL | H54: C | I54: 30000 | J54: 15.23 | K54: 1 | L54: 0.33 | M54: Y | N54: 3
C55: 23 | D55: 97000 | E55: RENT | F55: 7 | G55: VENTURE | H55: B | I55: 30000 | J55: 10.65 | K55: 1 | L55: 0.31 | M55: N | N55: 2
C56: 25 | D56: 120000 | E56: RENT | F56: 9 | G56: EDUCATION | H56: A | I56: 30000 | J56: 7.9 | K56: 0 | L56: 0.25 | M56: N | N56: 4
C57: 26 | D57: 280000 | E57: RENT | F57: 4 | G57: PERSONAL | H57: C | I57: 10000 | J57: 15.96 | K57: 0 | L57: 0.04 | M57: Y | N57: 3
C58: 26 | D58: 277104 | E58: RENT | F58: 0 | G58: VENTURE | H58: B | I58: 20000 | J58: 11.48 | K58: 0 | L58: 0.07 | M58: N | N58: 3
C59: 23 | D59: 277000 | E59: OWN | F59: 3 | G59: PERSONAL | H59: A | I59: 35000 | K59: 0 | L59: 0.13 | M59: N | N59: 4
C60: 25 | D60: 128000 | E60: RENT | F60: 9 | G60: PERSONAL | H60: A | I60: 30000 | J60: 7.29 | K60: 0 | L60: 0.23 | M60: N | N60: 4
C61: 24 | D61: 12000 | E61: OWN | F61: 2 | G61: VENTURE | H61: E | I61: 1750 | K61: 0 | L61: 0.15 | M61: Y | N61: 3
C62: 21 | D62: 131000 | E62: RENT | F62: 0 | G62: VENTURE | H62: A | I62: 30000 | J62: 5.99 | K62: 0 | L62: 0.23 | M62: N | N62: 4
C63: 22 | D63: 275000 | E63: OWN | F63: 6 | G63: VENTURE | H63: B | I63: 12000 | J63: 11.58 | K63: 0 | L63: 0.04 | M63: N | N63: 2
C64: 26 | D64: 263000 | E64: MORTGAGE | F64: 0 | G64: EDUCATION | H64: B | I64: 10000 | K64: 1 | L64: 0.04 | M64: N | N64: 4
C65: 25 | D65: 221850 | E65: MORTGAGE | F65: 9 | G65: MEDICAL | H65: D | I65: 25000 | J65: 15.7 | K65: 1 | L65: 0.1 | M65: N | N65: 2
C66: 22 | D66: 70000 | E66: RENT | F66: 6 | G66: EDUCATION | H66: D | I66: 29100 | J66: 15.99 | K66: 1 | L66: 0.42 | M66: N | N66: 3
...

Sheet Statistical-formulas
A1: Description | B1: Function | C1: person_age | D1: person_income | E1: person_home_ownership | F1: person_emp_length | G1: loan_intent | H1: loan_grade | I1: loan_amnt | J1: loan_int_rate | K1: loan_status | L1: loan_percent_income | M1: cb_person_default_on_file | N1: cb_person_cred_hist_length
A2: Minimum | B2: MIN | C2: =MIN(crisk!C:C) -> 20 | D2: =MIN(crisk!D:D) -> 4000 | F2: =MIN(crisk!F:F) -> 0 | I2: =MIN(crisk!I:I) -> 500 | J2: =MIN(crisk!J:J) -> 5.42 | K2: =MIN(crisk!K:K) -> 0 | L2: =MIN(crisk!L:L) -> 0 | N2: =MIN(crisk!N:N) -> 2
A3: Maximum | B3: MAX | C3: =MAX(crisk!C:C) -> 144 | D3: =MAX(crisk!D:D) -> 6000000 | F3: =MAX(crisk!F:F) -> 123 | I3: =MAX(crisk!I:I) -> 35000 | J3: =MAX(crisk!J:J) -> 23.22 | K3: =MAX(crisk!K:K) -> 1 | L3: =MAX(crisk!L:L) -> 0.83 | N3: =MAX(crisk!N:N) -> 30
A4: Mean | B4: AVERAGE | C4: =AVERAGE(crisk!C:C) -> 27.7346 | D4: =AVERAGE(crisk!D:D) -> 66074.848 | F4: =AVERAGE(crisk!F:F) -> 4.7896863 | I4: =AVERAGE(crisk!I:I) -> 9589.3711 | J4: =AVERAGE(crisk!J:J) -> 11.011695 | K4: =AVERAGE(crisk!K:K) -> 0.21816396 | L4: =AVERAGE(crisk!L:L) -> 0.17020349 | N4: =AVERAGE(crisk!N:N) -> 5.804211
A5: Median | B5: PERCENTILE | C5: =PERCENTILE(crisk!C:C, 0.5) -> 26 | D5: =PERCENTILE(crisk!D:D, 0.5) -> 55000 | F5: =PERCENTILE(crisk!F:F, 0.5) -> 4 | I5: =PERCENTILE(crisk!I:I, 0.5) -> 8000 | J5: =PERCENTILE(crisk!J:J, 0.5) -> 10.99 | K5: =PERCENTILE(crisk!K:K, 0.5) -> 0 | L5: =PERCENTILE(crisk!L:L, 0.5) -> 0.15 | N5: =PERCENTILE(crisk!N:N, 0.5) -> 4
A6: Nth Smallest | B6: SMALL | C6: =SMALL(crisk!C:C, 50) -> 21 | D6: =SMALL(crisk!D:D, 50) -> 9600 | F6: =SMALL(crisk!F:F, 50) -> 0 | I6: =SMALL(crisk!I:I, 50) -> 1000 | J6: =SMALL(crisk!J:J, 50) -> 5.42 | K6: =SMALL(crisk!K:K, 50) -> 0 | L6: =SMALL(crisk!L:L, 50) -> 0.01 | N6: =SMALL(crisk!N:N, 50) -> 2
A7: Nth Largest | B7: LARGE | C7: =LARGE(crisk!C:C, 100) -> 58 | D7: =LARGE(crisk!D:D, 100) -> 360000 | F7: =LARGE(crisk!F:F, 100) -> 21 | I7: =LARGE(crisk!I:I, 100) -> 35000 | J7: =LARGE(crisk!J:J, 100) -> 19.69 | K7: =LARGE(crisk!K:K, 100) -> 1 | L7: =LARGE(crisk!L:L, 100) -> 0.56 | N7: =LARGE(crisk!N:N, 100) -> 26
A8: Q1 (25% Percentile) | B8: PERCENTILE | C8: =PERCENTILE(crisk!C:C, 0.25) -> 23 | D8: =PERCENTILE(crisk!D:D, 0.25) -> 38500 | F8: =PERCENTILE(crisk!F:F, 0.25) -> 2 | I8: =PERCENTILE(crisk!I:I, 0.25) -> 5000 | J8: =PERCENTILE(crisk!J:J, 0.25) -> 7.9 | K8: =PERCENTILE(crisk!K:K, 0.25) -> 0 | L8: =PERCENTILE(crisk!L:L, 0.25) -> 0.09 | N8: =PERCENTILE(crisk!N:N, 0.25) -> 3
A9: Q3 (75% Percentile) | B9: PERCENTILE | C9: =PERCENTILE(crisk!C:C, 0.75) -> 30 | D9: =PERCENTILE(crisk!D:D, 0.75) -> 79200 | F9: =PERCENTILE(crisk!F:F, 0.75) -> 7 | I9: =PERCENTILE(crisk!I:I, 0.75) -> 12200 | J9: =PERCENTILE(crisk!J:J, 0.75) -> 13.47 | K9: =PERCENTILE(crisk!K:K, 0.75) -> 0 | L9: =PERCENTILE(crisk!L:L, 0.75) -> 0.23 | N9: =PERCENTILE(crisk!N:N, 0.75) -> 8
A10: 10th Percentile | B10: PERCENTILE | C10: =PERCENTILE(crisk!C:C, 0.1) -> 22 | D10: =PERCENTILE(crisk!D:D, 0.1) -> 28590 | F10: =PERCENTILE(crisk!F:F, 0.1) -> 0 | I10: =PERCENTILE(crisk!I:I, 0.1) -> 3000 | J10: =PERCENTILE(crisk!J:J, 0.1) -> 6.91 | K10: =PERCENTILE(crisk!K:K, 0.1) -> 0 | L10: =PERCENTILE(crisk!L:L, 0.1) -> 0.05 | N10: =PERCENTILE(crisk!N:N, 0.1) -> 2
A11: 90th Percentile | B11: PERCENTILE | C11: =PERCENTILE(crisk!C:C, 0.9) -> 36 | D11: =PERCENTILE(crisk!D:D, 0.9) -> 110004 | F11: =PERCENTILE(crisk!F:F, 0.9) -> 10 | I11: =PERCENTILE(crisk!I:I, 0.9) -> 19000 | J11: =PERCENTILE(crisk!J:J, 0.9) -> 15.298 | K11: =PERCENTILE(crisk!K:K, 0.9) -> 1 | L11: =PERCENTILE(crisk!L:L, 0.9) -> 0.32 | N11: =PERCENTILE(crisk!N:N, 0.9) -> 11
A13: FREQUENCY
A14: Count Observations | B14: COUNT | C14: =COUNT(crisk!C:C) -> 32581 | D14: =COUNT(crisk!D:D) -> 32581 | F14: =COUNT(crisk!F:F) -> 31686 | I14: =COUNT(crisk!I:I) -> 32581 | J14: =COUNT(crisk!J:J) -> 29465 | K14: =COUNT(crisk!K:K) -> 32581 | L14: =COUNT(crisk!L:L) -> 32581 | N14: =COUNT(crisk!N:N) -> 32581
A15: Count Missing Obs | B15: COUNTBLANK | C15: =COUNTBLANK(crisk!C1:C32582) -> 0 | D15: =COUNTBLANK(crisk!D1:D32582) -> 0 | F15: =COUNTBLANK(crisk!F1:F32582) -> 895 | I15: =COUNTBLANK(crisk!I1:I32582) -> 0 | J15: =COUNTBLANK(crisk!J1:J32582) -> 3116 | K15: =COUNTBLANK(crisk!K1:K32582) -> 0 | L15: =COUNTBLANK(crisk!L1:L32582) -> 0 | N15: =COUNTBLANK(crisk!N1:N32582) -> 0
A16: Conditional Count | B16: COUNTIF
B17: RENT | E17: =COUNTIF(crisk!E:E, "RENT") -> 16446
B18: OWN | E18: =COUNTIF(crisk!E:E, "OWN") -> 2584
B19: MORTAGE | E19: =COUNTIF(crisk!E:E, "MORTGAGE") -> 13444
B20: OTHER | E20: =COUNTIF(crisk!E:E, "OTHER") -> 107
E21: =SUM(E17:E20)-D14 -> 0
B23: COUNTIFS | E23: =COUNTIFS(crisk!E:E, "RENT", crisk!G:G, "PERSONAL", crisk!H:H, "A") -> 685
